{"asctime": "2025-03-28 17:21:22,663", "name": "__main__", "levelname": "DEBUG", "message": "Init Start"}
{"asctime": "2025-03-28 17:21:35,710", "name": "__main__", "levelname": "ERROR", "message": "Uncaught exception: Traceback (most recent call last):\n  File \"/home/codespace/.python/current/lib/python3.12/argparse.py\", line 2555, in _get_value\n    result = type_func(arg_string)\n             ^^^^^^^^^^^^^^^^^^^^^\n  File \"/workspaces/connect_four_mcts/common.py\", line 19, in file_exists\n    raise argparse.ArgumentTypeError(f\"'{path}' does not exist.\")\nargparse.ArgumentTypeError: 'test.txt' does not exist.\n\nDuring handling of the above exception, another exception occurred:\n\nTraceback (most recent call last):\n  File \"/home/codespace/.python/current/lib/python3.12/argparse.py\", line 1924, in parse_known_args\n    namespace, args = self._parse_known_args(args, namespace)\n                      ^^^^^^^^^^^^^^^^^^^^^^^^^^^^^^^^^^^^^^^\n  File \"/home/codespace/.python/current/lib/python3.12/argparse.py\", line 2139, in _parse_known_args\n    stop_index = consume_positionals(start_index)\n                 ^^^^^^^^^^^^^^^^^^^^^^^^^^^^^^^^\n  File \"/home/codespace/.python/current/lib/python3.12/argparse.py\", line 2095, in consume_positionals\n    take_action(action, args)\n  File \"/home/codespace/.python/current/lib/python3.12/argparse.py\", line 1984, in take_action\n    argument_values = self._get_values(action, argument_strings)\n                      ^^^^^^^^^^^^^^^^^^^^^^^^^^^^^^^^^^^^^^^^^^\n  File \"/home/codespace/.python/current/lib/python3.12/argparse.py\", line 2522, in _get_values\n    value = self._get_value(action, arg_string)\n            ^^^^^^^^^^^^^^^^^^^^^^^^^^^^^^^^^^^\n  File \"/home/codespace/.python/current/lib/python3.12/argparse.py\", line 2560, in _get_value\n    raise ArgumentError(action, msg)\nargparse.ArgumentError: argument input_file: 'test.txt' does not exist.\n\nDuring handling of the above exception, another exception occurred:\n\nTraceback (most recent call last):\n  File \"/workspaces/connect_four_mcts/main.py\", line 10, in main\n    input_file, verbosity, iterations = Common.Utils.validate_arguments()\n                                        ^^^^^^^^^^^^^^^^^^^^^^^^^^^^^^^^^\n  File \"/workspaces/connect_four_mcts/common.py\", line 44, in validate_arguments\n    args = parser.parse_args()\n           ^^^^^^^^^^^^^^^^^^^\n  File \"/home/codespace/.python/current/lib/python3.12/argparse.py\", line 1891, in parse_args\n    args, argv = self.parse_known_args(args, namespace)\n                 ^^^^^^^^^^^^^^^^^^^^^^^^^^^^^^^^^^^^^^\n  File \"/home/codespace/.python/current/lib/python3.12/argparse.py\", line 1926, in parse_known_args\n    self.error(str(err))\n  File \"/home/codespace/.python/current/lib/python3.12/argparse.py\", line 2655, in error\n    self.exit(2, _('%(prog)s: error: %(message)s\\n') % args)\n  File \"/home/codespace/.python/current/lib/python3.12/argparse.py\", line 2642, in exit\n    _sys.exit(status)\nSystemExit: 2\n"}
{"asctime": "2025-03-28 18:30:36,442", "name": "__main__", "levelname": "DEBUG", "message": "Init Start"}
{"asctime": "2025-03-28 18:30:40,675", "name": "__main__", "levelname": "ERROR", "message": "Uncaught exception: Traceback (most recent call last):\n  File \"/home/codespace/.python/current/lib/python3.12/argparse.py\", line 2555, in _get_value\n    result = type_func(arg_string)\n             ^^^^^^^^^^^^^^^^^^^^^\n  File \"/workspaces/connect_four_mcts/common.py\", line 36, in file_exists\n    raise argparse.ArgumentTypeError(f\"'{path}' does not exist.\")\nargparse.ArgumentTypeError: 'test.txt' does not exist.\n\nDuring handling of the above exception, another exception occurred:\n\nTraceback (most recent call last):\n  File \"/home/codespace/.python/current/lib/python3.12/argparse.py\", line 1924, in parse_known_args\n    namespace, args = self._parse_known_args(args, namespace)\n                      ^^^^^^^^^^^^^^^^^^^^^^^^^^^^^^^^^^^^^^^\n  File \"/home/codespace/.python/current/lib/python3.12/argparse.py\", line 2139, in _parse_known_args\n    stop_index = consume_positionals(start_index)\n                 ^^^^^^^^^^^^^^^^^^^^^^^^^^^^^^^^\n  File \"/home/codespace/.python/current/lib/python3.12/argparse.py\", line 2095, in consume_positionals\n    take_action(action, args)\n  File \"/home/codespace/.python/current/lib/python3.12/argparse.py\", line 1984, in take_action\n    argument_values = self._get_values(action, argument_strings)\n                      ^^^^^^^^^^^^^^^^^^^^^^^^^^^^^^^^^^^^^^^^^^\n  File \"/home/codespace/.python/current/lib/python3.12/argparse.py\", line 2522, in _get_values\n    value = self._get_value(action, arg_string)\n            ^^^^^^^^^^^^^^^^^^^^^^^^^^^^^^^^^^^\n  File \"/home/codespace/.python/current/lib/python3.12/argparse.py\", line 2560, in _get_value\n    raise ArgumentError(action, msg)\nargparse.ArgumentError: argument input_file: 'test.txt' does not exist.\n\nDuring handling of the above exception, another exception occurred:\n\nTraceback (most recent call last):\n  File \"/workspaces/connect_four_mcts/main.py\", line 10, in main\n    input_file, verbosity, iterations = Common.Utils.validate_arguments()\n                                        ^^^^^^^^^^^^^^^^^^^^^^^^^^^^^^^^^\n  File \"/workspaces/connect_four_mcts/common.py\", line 75, in validate_arguments\n    args = parser.parse_args()\n           ^^^^^^^^^^^^^^^^^^^\n  File \"/home/codespace/.python/current/lib/python3.12/argparse.py\", line 1891, in parse_args\n    args, argv = self.parse_known_args(args, namespace)\n                 ^^^^^^^^^^^^^^^^^^^^^^^^^^^^^^^^^^^^^^\n  File \"/home/codespace/.python/current/lib/python3.12/argparse.py\", line 1926, in parse_known_args\n    self.error(str(err))\n  File \"/home/codespace/.python/current/lib/python3.12/argparse.py\", line 2655, in error\n    self.exit(2, _('%(prog)s: error: %(message)s\\n') % args)\n  File \"/home/codespace/.python/current/lib/python3.12/argparse.py\", line 2642, in exit\n    _sys.exit(status)\nSystemExit: 2\n"}
{"asctime": "2025-03-28 18:33:14,051", "name": "__main__", "levelname": "DEBUG", "message": "Init Start"}
{"asctime": "2025-03-28 18:33:24,722", "name": "__main__", "levelname": "ERROR", "message": "Uncaught exception: Traceback (most recent call last):\n  File \"/home/codespace/.python/current/lib/python3.12/argparse.py\", line 2555, in _get_value\n    result = type_func(arg_string)\n             ^^^^^^^^^^^^^^^^^^^^^\n  File \"/workspaces/connect_four_mcts/common.py\", line 35, in file_exists\n    if not os.path.exists(path) or not os.path.exists(os.path.join(Common._basedir,path)):\n                                                      ^^^^^^^^^^^^^^^^^^^^^^^^^^^^^^^^^^\n  File \"/home/codespace/.python/current/lib/python3.12/posixpath.py\", line 76, in join\n    a = os.fspath(a)\n        ^^^^^^^^^^^^\nTypeError: expected str, bytes or os.PathLike object, not NoneType\n\nDuring handling of the above exception, another exception occurred:\n\nTraceback (most recent call last):\n  File \"/home/codespace/.python/current/lib/python3.12/argparse.py\", line 1924, in parse_known_args\n    namespace, args = self._parse_known_args(args, namespace)\n                      ^^^^^^^^^^^^^^^^^^^^^^^^^^^^^^^^^^^^^^^\n  File \"/home/codespace/.python/current/lib/python3.12/argparse.py\", line 2139, in _parse_known_args\n    stop_index = consume_positionals(start_index)\n                 ^^^^^^^^^^^^^^^^^^^^^^^^^^^^^^^^\n  File \"/home/codespace/.python/current/lib/python3.12/argparse.py\", line 2095, in consume_positionals\n    take_action(action, args)\n  File \"/home/codespace/.python/current/lib/python3.12/argparse.py\", line 1984, in take_action\n    argument_values = self._get_values(action, argument_strings)\n                      ^^^^^^^^^^^^^^^^^^^^^^^^^^^^^^^^^^^^^^^^^^\n  File \"/home/codespace/.python/current/lib/python3.12/argparse.py\", line 2522, in _get_values\n    value = self._get_value(action, arg_string)\n            ^^^^^^^^^^^^^^^^^^^^^^^^^^^^^^^^^^^\n  File \"/home/codespace/.python/current/lib/python3.12/argparse.py\", line 2567, in _get_value\n    raise ArgumentError(action, msg % args)\nargparse.ArgumentError: argument input_file: invalid file_exists value: 'test1.txt'\n\nDuring handling of the above exception, another exception occurred:\n\nTraceback (most recent call last):\n  File \"/workspaces/connect_four_mcts/main.py\", line 10, in main\n    input_file, verbosity, iterations = Common.Utils.validate_arguments()\n                                        ^^^^^^^^^^^^^^^^^^^^^^^^^^^^^^^^^\n  File \"/workspaces/connect_four_mcts/common.py\", line 75, in validate_arguments\n    args = parser.parse_args()\n           ^^^^^^^^^^^^^^^^^^^\n  File \"/home/codespace/.python/current/lib/python3.12/argparse.py\", line 1891, in parse_args\n    args, argv = self.parse_known_args(args, namespace)\n                 ^^^^^^^^^^^^^^^^^^^^^^^^^^^^^^^^^^^^^^\n  File \"/home/codespace/.python/current/lib/python3.12/argparse.py\", line 1926, in parse_known_args\n    self.error(str(err))\n  File \"/home/codespace/.python/current/lib/python3.12/argparse.py\", line 2655, in error\n    self.exit(2, _('%(prog)s: error: %(message)s\\n') % args)\n  File \"/home/codespace/.python/current/lib/python3.12/argparse.py\", line 2642, in exit\n    _sys.exit(status)\nSystemExit: 2\n"}
{"asctime": "2025-03-28 18:33:49,816", "name": "__main__", "levelname": "DEBUG", "message": "Init Start"}
{"asctime": "2025-03-28 18:39:11,520", "name": "__main__", "levelname": "DEBUG", "message": "Init Start"}
{"asctime": "2025-03-28 18:40:42,034", "name": "__main__", "levelname": "DEBUG", "message": "Init End"}
{"asctime": "2025-03-28 18:41:20,984", "name": "__main__", "levelname": "DEBUG", "message": "Init Start"}
{"asctime": "2025-03-28 18:41:27,889", "name": "__main__", "levelname": "DEBUG", "message": "Init End"}
{"asctime": "2025-03-28 18:41:27,889", "name": "__main__", "levelname": "DEBUG", "message": "Starting Game"}
{"asctime": "2025-03-28 18:41:27,890", "name": "__main__", "levelname": "DEBUG", "message": "Ending Game"}
{"asctime": "2025-03-28 18:41:41,381", "name": "__main__", "levelname": "DEBUG", "message": "Init Start"}
{"asctime": "2025-03-28 18:41:43,508", "name": "__main__", "levelname": "DEBUG", "message": "Init End"}
{"asctime": "2025-03-28 18:41:44,173", "name": "__main__", "levelname": "DEBUG", "message": "Starting Game"}
{"asctime": "2025-03-28 18:41:54,224", "name": "__main__", "levelname": "DEBUG", "message": "Ending Game"}
{"asctime": "2025-03-28 18:43:32,727", "name": "__main__", "levelname": "DEBUG", "message": "Init Start"}
{"asctime": "2025-03-28 18:43:32,738", "name": "__main__", "levelname": "ERROR", "message": "Uncaught exception: Traceback (most recent call last):\n  File \"/home/codespace/.python/current/lib/python3.12/argparse.py\", line 2555, in _get_value\n    result = type_func(arg_string)\n             ^^^^^^^^^^^^^^^^^^^^^\n  File \"/workspaces/connect_four_mcts/common.py\", line 44, in file_exists\n    raise argparse.ArgumentTypeError(f\"'{path}' does not exist.\")\nargparse.ArgumentTypeError: 'test2.txt' does not exist.\n\nDuring handling of the above exception, another exception occurred:\n\nTraceback (most recent call last):\n  File \"/home/codespace/.python/current/lib/python3.12/argparse.py\", line 1924, in parse_known_args\n    namespace, args = self._parse_known_args(args, namespace)\n                      ^^^^^^^^^^^^^^^^^^^^^^^^^^^^^^^^^^^^^^^\n  File \"/home/codespace/.python/current/lib/python3.12/argparse.py\", line 2139, in _parse_known_args\n    stop_index = consume_positionals(start_index)\n                 ^^^^^^^^^^^^^^^^^^^^^^^^^^^^^^^^\n  File \"/home/codespace/.python/current/lib/python3.12/argparse.py\", line 2095, in consume_positionals\n    take_action(action, args)\n  File \"/home/codespace/.python/current/lib/python3.12/argparse.py\", line 1984, in take_action\n    argument_values = self._get_values(action, argument_strings)\n                      ^^^^^^^^^^^^^^^^^^^^^^^^^^^^^^^^^^^^^^^^^^\n  File \"/home/codespace/.python/current/lib/python3.12/argparse.py\", line 2522, in _get_values\n    value = self._get_value(action, arg_string)\n            ^^^^^^^^^^^^^^^^^^^^^^^^^^^^^^^^^^^\n  File \"/home/codespace/.python/current/lib/python3.12/argparse.py\", line 2560, in _get_value\n    raise ArgumentError(action, msg)\nargparse.ArgumentError: argument input_file: 'test2.txt' does not exist.\n\nDuring handling of the above exception, another exception occurred:\n\nTraceback (most recent call last):\n  File \"/workspaces/connect_four_mcts/main.py\", line 10, in main\n    input_file, verbosity, iterations = Common.Utils.validate_arguments()\n                                        ^^^^^^^^^^^^^^^^^^^^^^^^^^^^^^^^^\n  File \"/workspaces/connect_four_mcts/common.py\", line 87, in validate_arguments\n    args = parser.parse_args()\n           ^^^^^^^^^^^^^^^^^^^\n  File \"/home/codespace/.python/current/lib/python3.12/argparse.py\", line 1891, in parse_args\n    args, argv = self.parse_known_args(args, namespace)\n                 ^^^^^^^^^^^^^^^^^^^^^^^^^^^^^^^^^^^^^^\n  File \"/home/codespace/.python/current/lib/python3.12/argparse.py\", line 1926, in parse_known_args\n    self.error(str(err))\n  File \"/home/codespace/.python/current/lib/python3.12/argparse.py\", line 2655, in error\n    self.exit(2, _('%(prog)s: error: %(message)s\\n') % args)\n  File \"/home/codespace/.python/current/lib/python3.12/argparse.py\", line 2642, in exit\n    _sys.exit(status)\nSystemExit: 2\n"}
{"asctime": "2025-03-28 18:43:54,841", "name": "__main__", "levelname": "DEBUG", "message": "Init Start"}
{"asctime": "2025-03-28 18:43:54,847", "name": "__main__", "levelname": "DEBUG", "message": "Init End"}
{"asctime": "2025-03-28 18:43:54,847", "name": "__main__", "levelname": "DEBUG", "message": "Starting Game"}
{"asctime": "2025-03-28 18:44:03,343", "name": "__main__", "levelname": "DEBUG", "message": "Ending Game"}
{"asctime": "2025-03-28 18:44:33,610", "name": "__main__", "levelname": "DEBUG", "message": "Init Start"}
{"asctime": "2025-03-28 18:44:35,568", "name": "__main__", "levelname": "DEBUG", "message": "Init End"}
{"asctime": "2025-03-28 18:44:36,613", "name": "__main__", "levelname": "DEBUG", "message": "Starting Game"}
{"asctime": "2025-03-28 18:44:39,943", "name": "__main__", "levelname": "DEBUG", "message": "Ending Game"}
{"asctime": "2025-03-28 18:44:53,588", "name": "__main__", "levelname": "DEBUG", "message": "Init Start"}
{"asctime": "2025-03-28 18:44:53,594", "name": "__main__", "levelname": "DEBUG", "message": "Init End"}
{"asctime": "2025-03-28 18:44:53,595", "name": "__main__", "levelname": "DEBUG", "message": "Starting Game"}
{"asctime": "2025-03-28 18:44:56,041", "name": "__main__", "levelname": "DEBUG", "message": "Ending Game"}
{"asctime": "2025-03-28 19:02:32,681", "name": "__main__", "levelname": "DEBUG", "message": "Init Start"}
{"asctime": "2025-03-28 19:03:15,796", "name": "__main__", "levelname": "ERROR", "message": "Uncaught exception: Traceback (most recent call last):\n  File \"/workspaces/connect_four_mcts/main.py\", line 12, in main\n    game = Connect4(algorithm_name, current_player, board, verbosity, iterations)\n           ^^^^^^^^^^^^^^^^^^^^^^^^^^^^^^^^^^^^^^^^^^^^^^^^^^^^^^^^^^^^^^^^^^^^^^\n  File \"/workspaces/connect_four_mcts/connect_4.py\", line 11, in __init__\n    self.algorithm = AlgorithmFactory.create_algorithm(algorithm_name)\n                     ^^^^^^^^^^^^^^^^^^^^^^^^^^^^^^^^^^^^^^^^^^^^^^^^^\n  File \"/workspaces/connect_four_mcts/common/utils.py\", line 136, in create_algorithm\n    raise ValueError(f\"Invalid algorithm name: {name}\")\nValueError: Invalid algorithm name: UCT\n"}
{"asctime": "2025-03-28 19:03:34,431", "name": "__main__", "levelname": "DEBUG", "message": "Init Start"}
{"asctime": "2025-03-28 19:04:34,960", "name": "__main__", "levelname": "DEBUG", "message": "Init Start"}
{"asctime": "2025-03-28 19:05:18,502", "name": "__main__", "levelname": "DEBUG", "message": "Init Start"}
{"asctime": "2025-03-28 19:05:32,224", "name": "__main__", "levelname": "ERROR", "message": "Uncaught exception: Traceback (most recent call last):\n  File \"/workspaces/connect_four_mcts/common/utils.py\", line 133, in create_algorithm\n    from algorithms.uct import UCT\n  File \"/workspaces/connect_four_mcts/algorithms/__init__.py\", line 1, in <module>\n    from .uniform_random import UniformRandom\n  File \"/workspaces/connect_four_mcts/algorithms/uniform_random.py\", line 1, in <module>\n    from algorithms import Base\nImportError: cannot import name 'Base' from partially initialized module 'algorithms' (most likely due to a circular import) (/workspaces/connect_four_mcts/algorithms/__init__.py)\n\nDuring handling of the above exception, another exception occurred:\n\nTraceback (most recent call last):\n  File \"/workspaces/connect_four_mcts/main.py\", line 12, in main\n    game = Connect4(algorithm_name, current_player, board, verbosity, iterations)\n           ^^^^^^^^^^^^^^^^^^^^^^^^^^^^^^^^^^^^^^^^^^^^^^^^^^^^^^^^^^^^^^^^^^^^^^\n  File \"/workspaces/connect_four_mcts/connect_4.py\", line 11, in __init__\n    self.algorithm = AlgorithmFactory.create_algorithm(algorithm_name.lower())\n                     ^^^^^^^^^^^^^^^^^^^^^^^^^^^^^^^^^^^^^^^^^^^^^^^^^^^^^^^^^\n  File \"/workspaces/connect_four_mcts/common/utils.py\", line 138, in create_algorithm\n    raise ValueError(f\"Error importing algorithm: {e}\")\nValueError: Error importing algorithm: cannot import name 'Base' from partially initialized module 'algorithms' (most likely due to a circular import) (/workspaces/connect_four_mcts/algorithms/__init__.py)\n"}
{"asctime": "2025-03-28 19:08:15,723", "name": "__main__", "levelname": "DEBUG", "message": "Init Start"}
{"asctime": "2025-03-28 19:09:48,166", "name": "__main__", "levelname": "DEBUG", "message": "Init Start"}
{"asctime": "2025-03-28 19:10:00,743", "name": "__main__", "levelname": "DEBUG", "message": "Init End"}
{"asctime": "2025-03-28 19:10:01,768", "name": "__main__", "levelname": "DEBUG", "message": "Starting Game"}
{"asctime": "2025-03-28 19:10:08,195", "name": "__main__", "levelname": "DEBUG", "message": "Ending Game"}
